Workbook
Name AttentionItem1Description: _calc_Attention!$D$30
Name AttentionItem1Icon: _calc_Attention!$F$30
Name AttentionItem1Priority: _calc_Attention!$B$30
Name AttentionItem1Severity: _calc_Attention!$E$30
Name AttentionItem1Source: _calc_Attention!$G$30
Name AttentionItem1Title: _calc_Attention!$C$30
Name AttentionItem2Description: _calc_Attention!$D$31
Name AttentionItem2Icon: _calc_Attention!$F$31
Name AttentionItem2Priority: _calc_Attention!$B$31
Name AttentionItem2Severity: _calc_Attention!$E$31
Name AttentionItem2Source: _calc_Attention!$G$31
Name AttentionItem2Title: _calc_Attention!$C$31
Name AttentionItem3Description: _calc_Attention!$D$32
Name AttentionItem3Icon: _calc_Attention!$F$32
Name AttentionItem3Priority: _calc_Attention!$B$32
Name AttentionItem3Severity: _calc_Attention!$E$32
Name AttentionItem3Source: _calc_Attention!$G$32
Name AttentionItem3Title: _calc_Attention!$C$32
Name AttentionItem4Description: _calc_Attention!$D$33
Name AttentionItem4Icon: _calc_Attention!$F$33
Name AttentionItem4Priority: _calc_Attention!$B$33
Name AttentionItem4Severity: _calc_Attention!$E$33
Name AttentionItem4Source: _calc_Attention!$G$33
Name AttentionItem4Title: _calc_Attention!$C$33
Name AttentionItem5Description: _calc_Attention!$D$34
Name AttentionItem5Icon: _calc_Attention!$F$34
Name AttentionItem5Priority: _calc_Attention!$B$34
Name AttentionItem5Severity: _calc_Attention!$E$34
Name AttentionItem5Source: _calc_Attention!$G$34
Name AttentionItem5Title: _calc_Attention!$C$34
Name AttentionItemCount: _calc_Attention!$B$35
Name calcAverageTransaction: _calc_Core!$B$8
Name calcCurrentMonth: _calc_Core!$B$2
Name calcHealthColor: _calc_Health!$B$34
Name calcHealthIcon: _calc_Health!$B$35
Name calcHealthScore: _calc_Health!$B$31
Name calcHealthState: _calc_Health!$B$30
Name calcHealthSubtitle: _calc_Health!$B$33
Name calcHealthTitle: _calc_Health!$B$32
Name calcMoneyInThisMonth: _calc_Core!$B$4
Name calcMoneyOutThisMonth: _calc_Core!$B$5
Name calcNetCashFlow: _calc_Core!$B$6
Name calcPreviousMonth: _calc_Core!$B$3
Name calcTransactionCount: _calc_Core!$B$7
Name CategoryNameList: tbl_Categories[CategoryName]
Name CelebrationsEnabledFlag: _data_Settings!$D$2
Name CurrencySymbol: IFERROR(INDEX(_lists_Validation!$U$2:$U$7,MATCH(CurrentCurrency,_lists_Validation!$T$2:$T$7,0)),"$")
Name CurrentAppVersion: _data_Settings!$G$2
Name CurrentBuildNumber: _data_Settings!$J$2
Name CurrentBusinessName: _data_BusinessProfile!$A$2
Name CurrentBusinessType: _data_BusinessProfile!$B$2
Name CurrentCurrency: _data_BusinessProfile!$D$2
Name CurrentDateFormat: _data_Settings!$A$2
Name CurrentFiscalYearStart: _data_BusinessProfile!$C$2
Name CurrentLastBriefingGeneratedDate: _data_Settings!$F$2
Name CurrentLastUpdated: _data_Settings!$K$2
Name CurrentLicense: _data_Settings!$L$2
Name CurrentLogoPlaceholder: _data_BusinessProfile!$G$2
Name CurrentNumberFormat: _data_Settings!$H$2
Name CurrentOwnerName: _data_BusinessProfile!$H$2

Sheet Home
B2: =CurrentBusinessName -> Riverside Design Studio | F2: Home | G2: Quick Add | H2: Bills | J2: Clients | K2: Goals | L2: Insights
B4: Home
B6: Business health
B7: =calcHealthTitle -> Excellent
B8: =calcHealthSubtitle -> Income is well ahead of spending this month
B10: Money in this month | F10: Money out this month
B11: =calcMoneyInThisMonth -> 850 | F11: =calcMoneyOutThisMonth -> 165
B15: Needs attention
B16: =AttentionItem1Title -> Overdue bills | J16: =AttentionItem1Severity -> Critical
B17: =AttentionItem2Title -> Overdue invoices | J17: =AttentionItem2Severity -> Critical
B18: =AttentionItem3Title | J18: =AttentionItem3Severity
B19: =AttentionItem4Title | J19: =AttentionItem4Severity
B20: =AttentionItem5Title | J20: =AttentionItem5Severity
B23: This week
B24: =_xlfn.TEXTJOIN(" ",TRUE(),InsightItem1Message,InsightItem2Message,InsightItem3Message) -> Your biggest expense this month was Supplies at $165. You paid City Wholesale Supplies more than anyone else this month, totaling $165. You've brought in $850 so far this month.

Sheet Settings
B2: Riverside Design Studio | F2: Home | G2: Quick Add | H2: Bills | J2: Clients | K2: Goals | L2: Insights
B4: Settings
B6: Business information
B7: Business name | F7: Riverside Design Studio
B8: Owner name (optional)
B9: Industry | F9: Freelance
B10: Currency | F10: USD
B11: Fiscal year start | F11: January
B12: Time zone | F12: America/New_York
B15: Appearance
B16: Theme | F16: Light
B17: Accent color | F17: Set by product (not user-editable in V1)
B18: Logo | F18: No logo uploaded
B21: Preferences
B22: Default date format | F22: MM/DD/YYYY
B23: Week start | F23: Sunday
B24: Number format | F24: US format
B27: Product information
B28: Version | F28: =CurrentAppVersion -> 1.0.4
B29: Build number | F29: =CurrentBuildNumber -> 2026.10.12-001
B30: Last updated | F30: =CurrentLastUpdated -> 46307
B31: License | F31: =CurrentLicense -> Licensed to Riverside Design Studio

Sheet Quick Add
B2: =CurrentBusinessName -> Riverside Design Studio | F2: Home | G2: Quick Add | H2: Bills | J2: Clients | K2: Goals | L2: Insights
B4: Quick Add
B6: What happened?
B7: Date | F7: =TODAY() -> 46307
B8: Money direction | F8: In
B9: Amount | F9: 850
B10: Category | F10: Other income
B11: Vendor / client | F11: Blue Harbor Cafe
B12: Description | F12: Website design deposit
B13: Notes (optional) | F13: 50% upfront payment
B16: =IF(OR(F8="",F9="",F10=""),"Ready to save — fill in the form above first","Ready to save") -> Ready to save
B17: This part is a manual step for now: select the row below, copy it, then paste it (as values) into the first empty row of your Transactions log. A future version may remove this step. See the developer notes for why this is required today.
B18: TransactionID | C18: Date | D18: Direction | E18: Amount | F18: CategoryID | G18: Description | H18: CustomerID | I18: VendorID | J18: RelatedInvoiceID | K18: RelatedBillID | L18: IsRecurring | M18: RecurrenceSourceID | N18: EntryMethod | O18: CreatedTimestamp
B19: {="TXN-"&TEXT(MAX(IFERROR(VALUE(MID(tbl_Transactions[TransactionID],5,10)),0))+1,"000000")} -> TXN-000485 | C19: =F7 -> 46307 | D19: =IF(F8="","",F8) -> In | E19: =IF(F9="","",F9) -> 850 | F19: =IFERROR(INDEX(tbl_Categories[CategoryID],MATCH(F10,tbl_Categories[CategoryName],0)),"") -> CAT-003 | G19: =IF(F13="",F12,F12&" -- Notes: "&F13) -> Website design deposit -- Notes: 50% upfront payment | H19: =IFERROR(INDEX(tbl_Customers[CustomerID],MATCH(F11,tbl_Customers[CustomerName],0)),"") -> CUS-001 | I19: =IFERROR(INDEX(tbl_Vendors[VendorID],MATCH(F11,tbl_Vendors[VendorName],0)),"") | L19: =FALSE() -> FALSE | N19: QuickAdd | O19: =NOW() -> 46307.095

Sheet Bills
B2: =CurrentBusinessName -> Riverside Design Studio | F2: Home | G2: Quick Add | H2: Bills | J2: Clients | K2: Goals | L2: Insights
B4: Bills & Subscriptions
B6: Upcoming & overdue
B7: Vendor | F7: Amount | H7: Due date | K7: Status
B8: =IFERROR(INDEX(tbl_Vendors[VendorName],MATCH(INDEX(tbl_Bills[VendorID],1),tbl_Vendors[VendorID],0)),"") -> City Wholesale Supplies | F8: =IFERROR(INDEX(tbl_Bills[Amount],1),"") -> 89 | H8: =IFERROR(INDEX(tbl_Bills[DueDate],1),"") -> 46318 | K8: =IFERROR(IF(INDEX(tbl_Bills[Status],1)="Paid","Paid",IF(INDEX(tbl_Bills[DueDate],1)="","",IF(INDEX(tbl_Bills[DueDate],1)<TODAY(),"Overdue","Upcoming"))),"") -> Upcoming
B9: =IFERROR(INDEX(tbl_Vendors[VendorName],MATCH(INDEX(tbl_Bills[VendorID],2),tbl_Vendors[VendorID],0)),"") -> City Wholesale Supplies | F9: =IFERROR(INDEX(tbl_Bills[Amount],2),"") -> 150 | H9: =IFERROR(INDEX(tbl_Bills[DueDate],2),"") -> 46301 | K9: =IFERROR(IF(INDEX(tbl_Bills[Status],2)="Paid","Paid",IF(INDEX(tbl_Bills[DueDate],2)="","",IF(INDEX(tbl_Bills[DueDate],2)<TODAY(),"Overdue","Upcoming"))),"") -> Overdue
B10: =IFERROR(INDEX(tbl_Vendors[VendorName],MATCH(INDEX(tbl_Bills[VendorID],3),tbl_Vendors[VendorID],0)),"") | F10: =IFERROR(INDEX(tbl_Bills[Amount],3),"") | H10: =IFERROR(INDEX(tbl_Bills[DueDate],3),"") | K10: =IFERROR(IF(INDEX(tbl_Bills[Status],3)="Paid","Paid",IF(INDEX(tbl_Bills[DueDate],3)="","",IF(INDEX(tbl_Bills[DueDate],3)<TODAY(),"Overdue","Upcoming"))),"")
B11: =IFERROR(INDEX(tbl_Vendors[VendorName],MATCH(INDEX(tbl_Bills[VendorID],4),tbl_Vendors[VendorID],0)),"") | F11: =IFERROR(INDEX(tbl_Bills[Amount],4),"") | H11: =IFERROR(INDEX(tbl_Bills[DueDate],4),"") | K11: =IFERROR(IF(INDEX(tbl_Bills[Status],4)="Paid","Paid",IF(INDEX(tbl_Bills[DueDate],4)="","",IF(INDEX(tbl_Bills[DueDate],4)<TODAY(),"Overdue","Upcoming"))),"")
B12: =IFERROR(INDEX(tbl_Vendors[VendorName],MATCH(INDEX(tbl_Bills[VendorID],5),tbl_Vendors[VendorID],0)),"") | F12: =IFERROR(INDEX(tbl_Bills[Amount],5),"") | H12: =IFERROR(INDEX(tbl_Bills[DueDate],5),"") | K12: =IFERROR(IF(INDEX(tbl_Bills[Status],5)="Paid","Paid",IF(INDEX(tbl_Bills[DueDate],5)="","",IF(INDEX(tbl_Bills[DueDate],5)<TODAY(),"Overdue","Upcoming"))),"")
B13: =IFERROR(INDEX(tbl_Vendors[VendorName],MATCH(INDEX(tbl_Bills[VendorID],6),tbl_Vendors[VendorID],0)),"") | F13: =IFERROR(INDEX(tbl_Bills[Amount],6),"") | H13: =IFERROR(INDEX(tbl_Bills[DueDate],6),"") | K13: =IFERROR(IF(INDEX(tbl_Bills[Status],6)="Paid","Paid",IF(INDEX(tbl_Bills[DueDate],6)="","",IF(INDEX(tbl_Bills[DueDate],6)<TODAY(),"Overdue","Upcoming"))),"")
B14: =IFERROR(INDEX(tbl_Vendors[VendorName],MATCH(INDEX(tbl_Bills[VendorID],7),tbl_Vendors[VendorID],0)),"") | F14: =IFERROR(INDEX(tbl_Bills[Amount],7),"") | H14: =IFERROR(INDEX(tbl_Bills[DueDate],7),"") | K14: =IFERROR(IF(INDEX(tbl_Bills[Status],7)="Paid","Paid",IF(INDEX(tbl_Bills[DueDate],7)="","",IF(INDEX(tbl_Bills[DueDate],7)<TODAY(),"Overdue","Upcoming"))),"")
B15: =IFERROR(INDEX(tbl_Vendors[VendorName],MATCH(INDEX(tbl_Bills[VendorID],8),tbl_Vendors[VendorID],0)),"") | F15: =IFERROR(INDEX(tbl_Bills[Amount],8),"") | H15: =IFERROR(INDEX(tbl_Bills[DueDate],8),"") | K15: =IFERROR(IF(INDEX(tbl_Bills[Status],8)="Paid","Paid",IF(INDEX(tbl_Bills[DueDate],8)="","",IF(INDEX(tbl_Bills[DueDate],8)<TODAY(),"Overdue","Upcoming"))),"")
B16: =IFERROR(INDEX(tbl_Vendors[VendorName],MATCH(INDEX(tbl_Bills[VendorID],9),tbl_Vendors[VendorID],0)),"") | F16: =IFERROR(INDEX(tbl_Bills[Amount],9),"") | H16: =IFERROR(INDEX(tbl_Bills[DueDate],9),"") | K16: =IFERROR(IF(INDEX(tbl_Bills[Status],9)="Paid","Paid",IF(INDEX(tbl_Bills[DueDate],9)="","",IF(INDEX(tbl_Bills[DueDate],9)<TODAY(),"Overdue","Upcoming"))),"")
B17: =IFERROR(INDEX(tbl_Vendors[VendorName],MATCH(INDEX(tbl_Bills[VendorID],10),tbl_Vendors[VendorID],0)),"") | F17: =IFERROR(INDEX(tbl_Bills[Amount],10),"") | H17: =IFERROR(INDEX(tbl_Bills[DueDate],10),"") | K17: =IFERROR(IF(INDEX(tbl_Bills[Status],10)="Paid","Paid",IF(INDEX(tbl_Bills[DueDate],10)="","",IF(INDEX(tbl_Bills[DueDate],10)<TODAY(),"Overdue","Upcoming"))),"")
B20: Add a bill
B21: Vendor
B22: Amount
B23: Due date
B24: Recurring?
B25: Recurrence frequency
B26: Notes (optional)
B29: =IF(OR(F21="",F22="",F23=""),"Ready to save — fill in the form above first","Ready to save") -> Ready to save — fill in the form above first
B30: Same manual step as Quick Add: select the row below, copy it, then paste it (as values) into the first empty row of your Bills table.
B31: BillID | C31: VendorID | D31: Amount | E31: DueDate | F31: IsRecurring | G31: RecurrenceFrequency | H31: Status | I31: LinkedTransactionID | J31: Notes
B32: {="BILL-"&TEXT(MAX(IFERROR(VALUE(MID(tbl_Bills[BillID],6,10)),0))+1,"0000")} -> BILL-0003 | C32: =IFERROR(INDEX(tbl_Vendors[VendorID],MATCH(F21,tbl_Vendors[VendorName],0)),"") | D32: =IF(F22="","",F22) | E32: =IF(F23="","",F23) | F32: =IF(F24="",FALSE,F24) -> FALSE | G32: =IF(F25="","",F25) | H32: =IF(F23="","",IF(F23<TODAY(),"Overdue","Upcoming")) | J32: =IF(F26="","",F26)

Sheet Clients
B2: =CurrentBusinessName -> Riverside Design Studio | F2: Home | G2: Quick Add | H2: Bills | J2: Clients | K2: Goals | L2: Insights
B4: Clients & Invoices
B6: Invoices
B7: Client | F7: Amount | H7: Due date | K7: Status
B8: =IFERROR(INDEX(tbl_Customers[CustomerName],MATCH(INDEX(tbl_Invoices[CustomerID],1),tbl_Customers[CustomerID],0)),"") -> Blue Harbor Cafe | F8: =IFERROR(INDEX(tbl_Invoices[Amount],1),"") -> 1200 | H8: =IFERROR(INDEX(tbl_Invoices[DueDate],1),"") -> 46291 | K8: =IFERROR(IF(OR(INDEX(tbl_Invoices[Status],1)="Paid",INDEX(tbl_Invoices[Status],1)="Void",INDEX(tbl_Invoices[Status],1)="Draft"),INDEX(tbl_Invoices[Status],1),IF(INDEX(tbl_Invoices[DueDate],1)="","",IF(INDEX(tbl_Invoices[DueDate],1)<TODAY(),"Overdue","Sent"))),"") -> Overdue
B9: =IFERROR(INDEX(tbl_Customers[CustomerName],MATCH(INDEX(tbl_Invoices[CustomerID],2),tbl_Customers[CustomerID],0)),"") -> Blue Harbor Cafe | F9: =IFERROR(INDEX(tbl_Invoices[Amount],2),"") -> 500 | H9: =IFERROR(INDEX(tbl_Invoices[DueDate],2),"") -> 46317 | K9: =IFERROR(IF(OR(INDEX(tbl_Invoices[Status],2)="Paid",INDEX(tbl_Invoices[Status],2)="Void",INDEX(tbl_Invoices[Status],2)="Draft"),INDEX(tbl_Invoices[Status],2),IF(INDEX(tbl_Invoices[DueDate],2)="","",IF(INDEX(tbl_Invoices[DueDate],2)<TODAY(),"Overdue","Sent"))),"") -> Sent
B10: =IFERROR(INDEX(tbl_Customers[CustomerName],MATCH(INDEX(tbl_Invoices[CustomerID],3),tbl_Customers[CustomerID],0)),"") | F10: =IFERROR(INDEX(tbl_Invoices[Amount],3),"") | H10: =IFERROR(INDEX(tbl_Invoices[DueDate],3),"") | K10: =IFERROR(IF(OR(INDEX(tbl_Invoices[Status],3)="Paid",INDEX(tbl_Invoices[Status],3)="Void",INDEX(tbl_Invoices[Status],3)="Draft"),INDEX(tbl_Invoices[Status],3),IF(INDEX(tbl_Invoices[DueDate],3)="","",IF(INDEX(tbl_Invoices[DueDate],3)<TODAY(),"Overdue","Sent"))),"")
B11: =IFERROR(INDEX(tbl_Customers[CustomerName],MATCH(INDEX(tbl_Invoices[CustomerID],4),tbl_Customers[CustomerID],0)),"") | F11: =IFERROR(INDEX(tbl_Invoices[Amount],4),"") | H11: =IFERROR(INDEX(tbl_Invoices[DueDate],4),"") | K11: =IFERROR(IF(OR(INDEX(tbl_Invoices[Status],4)="Paid",INDEX(tbl_Invoices[Status],4)="Void",INDEX(tbl_Invoices[Status],4)="Draft"),INDEX(tbl_Invoices[Status],4),IF(INDEX(tbl_Invoices[DueDate],4)="","",IF(INDEX(tbl_Invoices[DueDate],4)<TODAY(),"Overdue","Sent"))),"")
B12: =IFERROR(INDEX(tbl_Customers[CustomerName],MATCH(INDEX(tbl_Invoices[CustomerID],5),tbl_Customers[CustomerID],0)),"") | F12: =IFERROR(INDEX(tbl_Invoices[Amount],5),"") | H12: =IFERROR(INDEX(tbl_Invoices[DueDate],5),"") | K12: =IFERROR(IF(OR(INDEX(tbl_Invoices[Status],5)="Paid",INDEX(tbl_Invoices[Status],5)="Void",INDEX(tbl_Invoices[Status],5)="Draft"),INDEX(tbl_Invoices[Status],5),IF(INDEX(tbl_Invoices[DueDate],5)="","",IF(INDEX(tbl_Invoices[DueDate],5)<TODAY(),"Overdue","Sent"))),"")
B13: =IFERROR(INDEX(tbl_Customers[CustomerName],MATCH(INDEX(tbl_Invoices[CustomerID],6),tbl_Customers[CustomerID],0)),"") | F13: =IFERROR(INDEX(tbl_Invoices[Amount],6),"") | H13: =IFERROR(INDEX(tbl_Invoices[DueDate],6),"") | K13: =IFERROR(IF(OR(INDEX(tbl_Invoices[Status],6)="Paid",INDEX(tbl_Invoices[Status],6)="Void",INDEX(tbl_Invoices[Status],6)="Draft"),INDEX(tbl_Invoices[Status],6),IF(INDEX(tbl_Invoices[DueDate],6)="","",IF(INDEX(tbl_Invoices[DueDate],6)<TODAY(),"Overdue","Sent"))),"")
B14: =IFERROR(INDEX(tbl_Customers[CustomerName],MATCH(INDEX(tbl_Invoices[CustomerID],7),tbl_Customers[CustomerID],0)),"") | F14: =IFERROR(INDEX(tbl_Invoices[Amount],7),"") | H14: =IFERROR(INDEX(tbl_Invoices[DueDate],7),"") | K14: =IFERROR(IF(OR(INDEX(tbl_Invoices[Status],7)="Paid",INDEX(tbl_Invoices[Status],7)="Void",INDEX(tbl_Invoices[Status],7)="Draft"),INDEX(tbl_Invoices[Status],7),IF(INDEX(tbl_Invoices[DueDate],7)="","",IF(INDEX(tbl_Invoices[DueDate],7)<TODAY(),"Overdue","Sent"))),"")
B15: =IFERROR(INDEX(tbl_Customers[CustomerName],MATCH(INDEX(tbl_Invoices[CustomerID],8),tbl_Customers[CustomerID],0)),"") | F15: =IFERROR(INDEX(tbl_Invoices[Amount],8),"") | H15: =IFERROR(INDEX(tbl_Invoices[DueDate],8),"") | K15: =IFERROR(IF(OR(INDEX(tbl_Invoices[Status],8)="Paid",INDEX(tbl_Invoices[Status],8)="Void",INDEX(tbl_Invoices[Status],8)="Draft"),INDEX(tbl_Invoices[Status],8),IF(INDEX(tbl_Invoices[DueDate],8)="","",IF(INDEX(tbl_Invoices[DueDate],8)<TODAY(),"Overdue","Sent"))),"")
B16: =IFERROR(INDEX(tbl_Customers[CustomerName],MATCH(INDEX(tbl_Invoices[CustomerID],9),tbl_Customers[CustomerID],0)),"") | F16: =IFERROR(INDEX(tbl_Invoices[Amount],9),"") | H16: =IFERROR(INDEX(tbl_Invoices[DueDate],9),"") | K16: =IFERROR(IF(OR(INDEX(tbl_Invoices[Status],9)="Paid",INDEX(tbl_Invoices[Status],9)="Void",INDEX(tbl_Invoices[Status],9)="Draft"),INDEX(tbl_Invoices[Status],9),IF(INDEX(tbl_Invoices[DueDate],9)="","",IF(INDEX(tbl_Invoices[DueDate],9)<TODAY(),"Overdue","Sent"))),"")
B17: =IFERROR(INDEX(tbl_Customers[CustomerName],MATCH(INDEX(tbl_Invoices[CustomerID],10),tbl_Customers[CustomerID],0)),"") | F17: =IFERROR(INDEX(tbl_Invoices[Amount],10),"") | H17: =IFERROR(INDEX(tbl_Invoices[DueDate],10),"") | K17: =IFERROR(IF(OR(INDEX(tbl_Invoices[Status],10)="Paid",INDEX(tbl_Invoices[Status],10)="Void",INDEX(tbl_Invoices[Status],10)="Draft"),INDEX(tbl_Invoices[Status],10),IF(INDEX(tbl_Invoices[DueDate],10)="","",IF(INDEX(tbl_Invoices[DueDate],10)<TODAY(),"Overdue","Sent"))),"")
B20: Add an invoice
B21: Client
B22: Amount
B23: Due date
B24: Notes (optional)
B27: =IF(OR(F21="",F22="",F23=""),"Ready to save — fill in the form above first","Ready to save") -> Ready to save — fill in the form above first
B28: Same manual step as Quick Add and Bills: select the row below, copy it, then paste it (as values) into the first empty row of your Invoices table.
B29: InvoiceID | C29: CustomerID | D29: IssueDate | E29: DueDate | F29: Amount | G29: Status | H29: PaidDate | I29: LinkedTransactionID | J29: Notes
B30: {="INV-"&TEXT(MAX(IFERROR(VALUE(MID(tbl_Invoices[InvoiceID],5,10)),0))+1,"0000")} -> INV-0003 | C30: =IFERROR(INDEX(tbl_Customers[CustomerID],MATCH(F21,tbl_Customers[CustomerName],0)),"") | D30: =TODAY() -> 46307 | E30: =IF(F23="","",F23) | F30: =IF(F22="","",F22) | G30: =IF(F23="","",IF(F23<TODAY(),"Overdue","Sent")) | J30: =IF(F24="","",F24)

Sheet Goals
B2: =CurrentBusinessName -> Riverside Design Studio | F2: Home | G2: Quick Add | H2: Bills | J2: Clients | K2: Goals | L2: Insights
B4: Goals
B6: Your goals
B7: Goal | F7: Progress | H7: Target date | K7: Status
B8: =IFERROR(INDEX(tbl_Goals[GoalName],1),"") -> Emergency Fund | F8: =IF(B8="","",CurrencySymbol&TEXT(INDEX(tbl_Goals[CurrentAmount],1),"#,##0")&" of "&CurrencySymbol&TEXT(INDEX(tbl_Goals[TargetAmount],1),"#,##0")&" ("&TEXT(INDEX(tbl_Goals[CurrentAmount],1)/INDEX(tbl_Goals[TargetAmount],1),"0%")&")") -> $5,580 of $9,000 (62%) | H8: =IFERROR(INDEX(tbl_Goals[TargetDate],1),"") -> 46387 | K8: =IFERROR(INDEX(tbl_Goals[Status],1),"") -> Active
B9: =IFERROR(INDEX(tbl_Goals[GoalName],2),"") | F9: =IF(B9="","",CurrencySymbol&TEXT(INDEX(tbl_Goals[CurrentAmount],2),"#,##0")&" of "&CurrencySymbol&TEXT(INDEX(tbl_Goals[TargetAmount],2),"#,##0")&" ("&TEXT(INDEX(tbl_Goals[CurrentAmount],2)/INDEX(tbl_Goals[TargetAmount],2),"0%")&")") | H9: =IFERROR(INDEX(tbl_Goals[TargetDate],2),"") | K9: =IFERROR(INDEX(tbl_Goals[Status],2),"")
B10: =IFERROR(INDEX(tbl_Goals[GoalName],3),"") | F10: =IF(B10="","",CurrencySymbol&TEXT(INDEX(tbl_Goals[CurrentAmount],3),"#,##0")&" of "&CurrencySymbol&TEXT(INDEX(tbl_Goals[TargetAmount],3),"#,##0")&" ("&TEXT(INDEX(tbl_Goals[CurrentAmount],3)/INDEX(tbl_Goals[TargetAmount],3),"0%")&")") | H10: =IFERROR(INDEX(tbl_Goals[TargetDate],3),"") | K10: =IFERROR(INDEX(tbl_Goals[Status],3),"")
B11: =IFERROR(INDEX(tbl_Goals[GoalName],4),"") | F11: =IF(B11="","",CurrencySymbol&TEXT(INDEX(tbl_Goals[CurrentAmount],4),"#,##0")&" of "&CurrencySymbol&TEXT(INDEX(tbl_Goals[TargetAmount],4),"#,##0")&" ("&TEXT(INDEX(tbl_Goals[CurrentAmount],4)/INDEX(tbl_Goals[TargetAmount],4),"0%")&")") | H11: =IFERROR(INDEX(tbl_Goals[TargetDate],4),"") | K11: =IFERROR(INDEX(tbl_Goals[Status],4),"")
B12: =IFERROR(INDEX(tbl_Goals[GoalName],5),"") | F12: =IF(B12="","",CurrencySymbol&TEXT(INDEX(tbl_Goals[CurrentAmount],5),"#,##0")&" of "&CurrencySymbol&TEXT(INDEX(tbl_Goals[TargetAmount],5),"#,##0")&" ("&TEXT(INDEX(tbl_Goals[CurrentAmount],5)/INDEX(tbl_Goals[TargetAmount],5),"0%")&")") | H12: =IFERROR(INDEX(tbl_Goals[TargetDate],5),"") | K12: =IFERROR(INDEX(tbl_Goals[Status],5),"")
B13: =IFERROR(INDEX(tbl_Goals[GoalName],6),"") | F13: =IF(B13="","",CurrencySymbol&TEXT(INDEX(tbl_Goals[CurrentAmount],6),"#,##0")&" of "&CurrencySymbol&TEXT(INDEX(tbl_Goals[TargetAmount],6),"#,##0")&" ("&TEXT(INDEX(tbl_Goals[CurrentAmount],6)/INDEX(tbl_Goals[TargetAmount],6),"0%")&")") | H13: =IFERROR(INDEX(tbl_Goals[TargetDate],6),"") | K13: =IFERROR(INDEX(tbl_Goals[Status],6),"")
B16: Add a goal
B17: Goal name
B18: Goal type
B19: Target amount
B20: Target date (optional)
B23: =IF(OR(F17="",F18="",F19=""),"Ready to save — fill in the form above first","Ready to save") -> Ready to save — fill in the form above first
B24: Same manual step as Quick Add, Bills, and Clients: select the row below, copy it, then paste it (as values) into the first empty row of your Goals table. New goals start at zero progress and Active status.
B25: GoalID | C25: GoalName | D25: GoalType | E25: TargetAmount | F25: CurrentAmount | G25: StartDate | H25: TargetDate | I25: Status | J25: IconTag
B26: {="GOAL-"&TEXT(MAX(IFERROR(VALUE(MID(tbl_Goals[GoalID],6,10)),0))+1,"000")} -> GOAL-002 | C26: =IF(F17="","",F17) | D26: =IF(F18="","",F18) | E26: =IF(F19="","",F19) | F26: 0 | G26: =TODAY() -> 46307 | H26: =IF(F20="","",F20) | I26: Active | J26: flag

Sheet _data_Transactions
A1: TransactionID | B1: Date | C1: Direction | D1: Amount | E1: CategoryID | F1: Description | G1: CustomerID | H1: VendorID | I1: RelatedInvoiceID | J1: RelatedBillID | K1: IsRecurring | L1: RecurrenceSourceID | M1: EntryMethod | N1: CreatedTimestamp
A2: TXN-000482 | B2: =MAX(DATE(YEAR(TODAY()),MONTH(TODAY()),1),TODAY()-1) -> 46306 | C2: Out | D2: 45 | E2: CAT-007 | F2: Coffee shop supplies | H2: VEN-007 | K2: =FALSE() -> FALSE | M2: Sample | N2: Sample data
A3: TXN-000483 | B3: =MAX(DATE(YEAR(TODAY()),MONTH(TODAY()),1),TODAY()-3) -> 46304 | C3: In | D3: 850 | E3: CAT-001 | F3: Website design deposit | G3: CUS-001 | K3: =FALSE() -> FALSE | M3: Sample | N3: Sample data
A4: TXN-000484 | B4: =MAX(DATE(YEAR(TODAY()),MONTH(TODAY()),1),TODAY()-2) -> 46305 | C4: Out | D4: 120 | E4: CAT-007 | F4: Supply order | H4: VEN-007 | K4: =FALSE() -> FALSE | M4: Sample | N4: Sample data

Sheet _data_Categories
A1: CategoryID | B1: CategoryName | C1: Direction | D1: IsSystemDefault | E1: IsArchived | F1: IconTag
A2: CAT-001 | B2: Client payments | C2: In | D2: =TRUE() -> TRUE | E2: =FALSE() -> FALSE | F2: money-in
A3: CAT-002 | B3: Product sales | C3: In | D3: =TRUE() -> TRUE | E3: =FALSE() -> FALSE | F3: cart
A4: CAT-003 | B4: Other income | C4: In | D4: =TRUE() -> TRUE | E4: =FALSE() -> FALSE | F4: plus-circle
A5: CAT-004 | B5: Rent | C5: Out | D5: =TRUE() -> TRUE | E5: =FALSE() -> FALSE | F5: building
A6: CAT-005 | B6: Utilities | C6: Out | D6: =TRUE() -> TRUE | E6: =FALSE() -> FALSE | F6: bolt
A7: CAT-006 | B7: Software subscriptions | C7: Out | D7: =TRUE() -> TRUE | E7: =FALSE() -> FALSE | F7: laptop
A8: CAT-007 | B8: Supplies | C8: Out | D8: =TRUE() -> TRUE | E8: =FALSE() -> FALSE | F8: box
A9: CAT-008 | B9: Payroll | C9: Out | D9: =TRUE() -> TRUE | E9: =FALSE() -> FALSE | F9: users
A10: CAT-009 | B10: Marketing | C10: Out | D10: =TRUE() -> TRUE | E10: =FALSE() -> FALSE | F10: megaphone
A11: CAT-010 | B11: Insurance | C11: Out | D11: =TRUE() -> TRUE | E11: =FALSE() -> FALSE | F11: shield
A12: CAT-011 | B12: Contractor payments | C12: Out | D12: =TRUE() -> TRUE | E12: =FALSE() -> FALSE | F12: briefcase
A13: CAT-012 | B13: Other expenses | C13: Out | D13: =TRUE() -> TRUE | E13: =FALSE() -> FALSE | F13: dots

Sheet _data_Vendors
A1: VendorID | B1: VendorName | C1: Email | D1: Phone | E1: DefaultCategoryID | F1: Notes | G1: IsArchived
A2: VEN-007 | B2: City Wholesale Supplies | C2: orders@citywholesale.com | D2: 555-0142 | E2: CAT-007 | G2: =FALSE() -> FALSE

Sheet _data_Bills
A1: BillID | B1: VendorID | C1: Amount | D1: DueDate | E1: IsRecurring | F1: RecurrenceFrequency | G1: Status | H1: LinkedTransactionID | I1: Notes
A2: BILL-0001 | B2: VEN-007 | C2: 89 | D2: =TODAY()+11 -> 46318 | E2: =TRUE() -> TRUE | F2: Monthly | G2: Upcoming | I2: Software subscription
A3: BILL-0002 | B3: VEN-007 | C3: 150 | D3: =TODAY()-6 -> 46301 | E3: =FALSE() -> FALSE | F3: None | G3: Overdue | I3: Supply order invoice

Sheet _data_Customers
A1: CustomerID | B1: CustomerName | C1: Email | D1: Phone | E1: Notes | F1: IsArchived
A2: CUS-001 | B2: Blue Harbor Cafe | C2: hello@blueharborcafe.com | F2: =FALSE() -> FALSE

Sheet _data_Invoices
A1: InvoiceID | B1: CustomerID | C1: IssueDate | D1: DueDate | E1: Amount | F1: Status | G1: PaidDate | H1: LinkedTransactionID | I1: Notes
A2: INV-0001 | B2: CUS-001 | C2: =TODAY()-30 -> 46277 | D2: =TODAY()-16 -> 46291 | E2: 1200 | F2: Overdue | I2: Logo design project
A3: INV-0002 | B3: CUS-001 | C3: =TODAY()-4 -> 46303 | D3: =TODAY()+10 -> 46317 | E3: 500 | F3: Sent | I3: Website update

Sheet _data_Goals
A1: GoalID | B1: GoalName | C1: GoalType | D1: TargetAmount | E1: CurrentAmount | F1: StartDate | G1: TargetDate | H1: Status | I1: IconTag
A2: GOAL-001 | B2: Emergency Fund | C2: Savings | D2: 9000 | E2: 5580 | F2: =DATE(YEAR(TODAY()),1,1) -> 46023 | G2: =DATE(YEAR(TODAY()),12,31) -> 46387 | H2: Active | I2: shield

Sheet _data_BusinessProfile
A1: BusinessName | B1: BusinessType | C1: FiscalYearStartMonth | D1: Currency | E1: StartingCashBalance | F1: SetupCompletedDate | G1: LogoPlaceholder | H1: OwnerName | I1: TimeZone
A2: =Settings!F7 -> Riverside Design Studio | B2: =Settings!F9 -> Freelance | C2: =Settings!F11 -> January | D2: =Settings!F10 -> USD | E2: 2500 | F2: 46025 | G2: =Settings!F18 -> No logo uploaded | H2: =Settings!F8 -> 0 | I2: =Settings!F12 -> America/New_York

Sheet _data_Settings
A1: DateFormatPreference | B1: WeekStartDay | C1: InsightsEnabled | D1: CelebrationAnimationsEnabled | E1: DefaultInvoiceDueDays | F1: LastBriefingGeneratedDate | G1: AppVersion | H1: NumberFormat | I1: Theme | J1: BuildNumber | K1: LastUpdated | L1: License
A2: =Settings!F22 -> MM/DD/YYYY | B2: =Settings!F23 -> Sunday | C2: =TRUE() -> TRUE | D2: =TRUE() -> TRUE | E2: 14 | F2: 46216 | G2: 1.0.4 | H2: =Settings!F24 -> US format | I2: =Settings!F16 -> Light | J2: 2026.10.12-001 | K2: 46307 | L2: Licensed to Riverside Design Studio

Sheet _calc_Core
A2: Current Month | B2: =DATE(YEAR(TODAY()),MONTH(TODAY()),1) -> 46296
A3: Previous Month | B3: =EDATE(B2,-1) -> 46266
A4: Money In This Month | B4: =SUMIFS(tbl_Transactions[Amount],tbl_Transactions[Direction],"In",tbl_Transactions[Date],">="&B2,tbl_Transactions[Date],"<"&EDATE(B2,1)) -> 850
A5: Money Out This Month | B5: =SUMIFS(tbl_Transactions[Amount],tbl_Transactions[Direction],"Out",tbl_Transactions[Date],">="&B2,tbl_Transactions[Date],"<"&EDATE(B2,1)) -> 165
A6: Net Cash Flow | B6: =B4-B5 -> 685
A7: Transaction Count | B7: =COUNTIFS(tbl_Transactions[Date],">="&B2,tbl_Transactions[Date],"<"&EDATE(B2,1)) -> 3
A8: Average Transaction | B8: =IFERROR(AVERAGEIFS(tbl_Transactions[Amount],tbl_Transactions[Date],">="&B2,tbl_Transactions[Date],"<"&EDATE(B2,1)),0) -> 338.33333

Sheet _calc_Health
A2: SECTION 1: INPUTS (from _calc_Core only)
A3: Money In This Month | B3: =calcMoneyInThisMonth -> 850
A4: Money Out This Month | B4: =calcMoneyOutThisMonth -> 165
A5: Net Cash Flow | B5: =calcNetCashFlow -> 685
A6: Transaction Count | B6: =calcTransactionCount -> 3
A7: Average Transaction | B7: =calcAverageTransaction -> 338.33333
A8: Current Month | B8: =calcCurrentMonth -> 46296
A9: Previous Month | B9: =calcPreviousMonth -> 46266
A10: Cash Runway (months) - TODO: not yet available, pending Cash Runway calc engine
A11: Overdue Bills Count - TODO: not yet available, pending Bills data layer
A12: Overdue Invoices Count - TODO: not yet available, pending Invoices data layer
A14: SECTION 2: INTERMEDIATE CALCULATIONS
A15: Has Activity This Month | B15: =IF(B6>0,1,0) -> 1
A16: Cash Flow Ratio (Money In / Money Out) | B16: =IFERROR(B3/B4,IF(B3>0,999,0)) -> 5.1515152
A18: SECTION 3: THRESHOLD EVALUATION (weighted scoring)
A19: Cash Flow Score (0-50) - REAL | B19: =IF(B16>=1.5,50,IF(B16>=1.1,40,IF(B16>=0.9,28,IF(B16>=0.6,16,5)))) -> 50
A20: Activity Score (0-10) - REAL | B20: =IF(B15=1,10,0) -> 10
A21: Cash Runway Score (0-25) - PLACEHOLDER, not yet implemented | B21: 0
A22: Bills Score (0-10) - PLACEHOLDER, not yet implemented | B22: 0
A23: Invoice Score (0-5) - PLACEHOLDER, not yet implemented | B23: 0
A24: Partial Score (Cash Flow + Activity only - drives State today) | B24: =B19+B20 -> 60
A25: Total Score (all 5 components - nominal 0-100, not yet meaningful) | B25: =B19+B20+B21+B22+B23 -> 60
A26: Health State (raw) | B26: =IF(B15=0,"Getting started",IF(B24>=55,"Excellent",IF(B24>=45,"Good",IF(B24>=32,"Fair",IF(B24>=20,"Warning","Critical"))))) -> Excellent
A27: Health Score (raw, -1 sentinel for Getting started) | B27: =IF(B15=0,-1,B25) -> 60
A29: SECTION 4: OUTPUT VALUES
A30: Health State (final) | B30: =B26 -> Excellent
A31: Health Score (final) | B31: =B27 -> 60
A32: Health Title | B32: =INDEX($F$40:$F$45,MATCH($B$26,$D$40:$D$45,0)) -> Excellent
A33: Health Subtitle | B33: =INDEX($G$40:$G$45,MATCH($B$26,$D$40:$D$45,0)) -> Income is well ahead of spending this month
A34: Health Color | B34: =INDEX($H$40:$H$45,MATCH($B$26,$D$40:$D$45,0)) -> Success
A35: Health Icon | B35: =INDEX($I$40:$I$45,MATCH($B$26,$D$40:$D$45,0)) -> star
D38: Reference: state lookup table (Section 4 support data)
D39: State | E39: Representative Score | F39: Title | G39: Subtitle | H39: Color | I39: Icon
D40: Getting started | E40: -1 | F40: Getting started | G40: Log your first transaction to see your business health | H40: Neutral | I40: flag
D41: Critical | E41: 15 | F41: Needs attention | G41: Spending is significantly outpacing income this month | H41: Critical | I41: alert-triangle
D42: Warning | E42: 26 | F42: Caution | G42: Spending is higher than income this month | H42: Warning | I42: alert-circle
D43: Fair | E43: 38 | F43: Steady | G43: Income and spending are about even this month | H43: Neutral | I43: minus-circle
D44: Good | E44: 50 | F44: Good | G44: Income is ahead of spending this month | H44: Success | I44: trending-up
D45: Excellent | E45: 60 | F45: Excellent | G45: Income is well ahead of spending this month | H45: Success | I45: star

Sheet _calc_Attention
A2: SECTION 1: INPUTS (from _calc_Core only)
A3: Money In This Month | B3: =calcMoneyInThisMonth -> 850
A4: Money Out This Month | B4: =calcMoneyOutThisMonth -> 165
A5: Net Cash Flow | B5: =calcNetCashFlow -> 685
A6: Transaction Count | B6: =calcTransactionCount -> 3
A7: Overdue Bills Count | B7: =SUMPRODUCT((tbl_Bills[Status]<>"Paid")*(tbl_Bills[DueDate]<>"")*(tbl_Bills[DueDate]<TODAY())) -> 1
A8: Overdue Invoices Count | B8: =SUMPRODUCT((tbl_Invoices[Status]<>"Paid")*(tbl_Invoices[Status]<>"Void")*(tbl_Invoices[Status]<>"Draft")*(tbl_Invoices[DueDate]<>"")*(tbl_Invoices[DueDate]<TODAY())) -> 1
A9: Upcoming Loan Payments - TODO: not yet available, pending Loans data layer
A11: SECTION 2: RULE EVALUATION
A12: RuleID | B12: Priority | C12: Fired | D12: Title | E12: Description | F12: Severity | G12: Icon | H12: Source
A13: R1 | B13: 1 | C13: =IF($B$6=0,1,0) -> 0 | D13: Get started | E13: No transactions logged yet this month. Add one to see your business health. | F13: Info | G13: flag | H13: _calc_Core
A14: R2 | B14: 2 | C14: =IF(AND($B$3=0,$B$6>0),1,0) -> 0 | D14: No income logged | E14: You haven't logged any income this month yet. | F14: Critical | G14: alert-triangle | H14: _calc_Core
A15: R3 | B15: 3 | C15: =IF(AND($B$5<0,$B$3>0),1,0) -> 0 | D15: Spending more than you're making | E15: Your expenses this month are higher than your income so far. | F15: Warning | G15: alert-circle | H15: _calc_Core
A16: R4 | B16: 4 | C16: =IF(AND($B$4=0,$B$6>0),1,0) -> 0 | D16: No expenses logged | E16: You've logged income this month but no expenses yet - worth double-checking you haven't missed any. | F16: Info | G16: info-circle | H16: _calc_Core
A17: R5 | B17: 5 | C17: =IF($B$7>0,1,0) -> 1 | D17: Overdue bills | E17: ="You have "&$B$7&" overdue bill"&IF($B$7=1,"","s")&" totaling "&CurrencySymbol&TEXT(SUMPRODUCT((tbl_Bills[Status]<>"Paid")*(tbl_Bills[DueDate]<>"")*(tbl_Bills[DueDate]<TODAY())*tbl_Bills[Amount]),"#,##0")&"." -> You have 1 overdue bill totaling $150. | F17: Critical | G17: alert-triangle | H17: tbl_Bills
A18: R6 | B18: 6 | C18: =IF($B$8>0,1,0) -> 1 | D18: Overdue invoices | E18: ="You have "&$B$8&" overdue invoice"&IF($B$8=1,"","s")&" worth "&CurrencySymbol&TEXT(SUMPRODUCT((tbl_Invoices[Status]<>"Paid")*(tbl_Invoices[Status]<>"Void")*(tbl_Invoices[Status]<>"Draft")*(tbl_Invoices[DueDate]<>"")*(tbl_Invoices[DueDate]<TODAY())*tbl_Invoices[Amount]),"#,##0")&"." -> You have 1 overdue invoice worth $1,200. | F18: Critical | G18: alert-triangle | H18: tbl_Invoices
A19: R7 | B19: 7 | C19: 0 | D19: TODO: Upcoming loan payment | E19: TODO: not yet available, pending Loans data layer | F19: TODO | G19: TODO | H19: tbl_Loans (not yet built)
A21: SECTION 3: PRIORITY SORTING
A22: Slot 1 Priority | B22: {=IFERROR(SMALL(IF($C$13:$C$19=1,$B$13:$B$19),1),"")} -> 5
A23: Slot 2 Priority | B23: {=IFERROR(SMALL(IF($C$13:$C$19=1,$B$13:$B$19),2),"")} -> 6
A24: Slot 3 Priority | B24: {=IFERROR(SMALL(IF($C$13:$C$19=1,$B$13:$B$19),3),"")}
A25: Slot 4 Priority | B25: {=IFERROR(SMALL(IF($C$13:$C$19=1,$B$13:$B$19),4),"")}
A26: Slot 5 Priority | B26: {=IFERROR(SMALL(IF($C$13:$C$19=1,$B$13:$B$19),5),"")}
A28: SECTION 4: OUTPUT VALUES
A29: Output Item | B29: Priority | C29: Title | D29: Description | E29: Severity | F29: Icon | G29: Source
A30: Item 1 | B30: =B22 -> 5 | C30: =IFERROR(INDEX($D$13:$D$19,MATCH($B30,$B$13:$B$19,0)),"") -> Overdue bills | D30: =IFERROR(INDEX($E$13:$E$19,MATCH($B30,$B$13:$B$19,0)),"") -> You have 1 overdue bill totaling $150. | E30: =IFERROR(INDEX($F$13:$F$19,MATCH($B30,$B$13:$B$19,0)),"") -> Critical | F30: =IFERROR(INDEX($G$13:$G$19,MATCH($B30,$B$13:$B$19,0)),"") -> alert-triangle | G30: =IFERROR(INDEX($H$13:$H$19,MATCH($B30,$B$13:$B$19,0)),"") -> tbl_Bills
A31: Item 2 | B31: =B23 -> 6 | C31: =IFERROR(INDEX($D$13:$D$19,MATCH($B31,$B$13:$B$19,0)),"") -> Overdue invoices | D31: =IFERROR(INDEX($E$13:$E$19,MATCH($B31,$B$13:$B$19,0)),"") -> You have 1 overdue invoice worth $1,200. | E31: =IFERROR(INDEX($F$13:$F$19,MATCH($B31,$B$13:$B$19,0)),"") -> Critical | F31: =IFERROR(INDEX($G$13:$G$19,MATCH($B31,$B$13:$B$19,0)),"") -> alert-triangle | G31: =IFERROR(INDEX($H$13:$H$19,MATCH($B31,$B$13:$B$19,0)),"") -> tbl_Invoices
A32: Item 3 | B32: =B24 | C32: =IFERROR(INDEX($D$13:$D$19,MATCH($B32,$B$13:$B$19,0)),"") | D32: =IFERROR(INDEX($E$13:$E$19,MATCH($B32,$B$13:$B$19,0)),"") | E32: =IFERROR(INDEX($F$13:$F$19,MATCH($B32,$B$13:$B$19,0)),"") | F32: =IFERROR(INDEX($G$13:$G$19,MATCH($B32,$B$13:$B$19,0)),"") | G32: =IFERROR(INDEX($H$13:$H$19,MATCH($B32,$B$13:$B$19,0)),"")
A33: Item 4 | B33: =B25 | C33: =IFERROR(INDEX($D$13:$D$19,MATCH($B33,$B$13:$B$19,0)),"") | D33: =IFERROR(INDEX($E$13:$E$19,MATCH($B33,$B$13:$B$19,0)),"") | E33: =IFERROR(INDEX($F$13:$F$19,MATCH($B33,$B$13:$B$19,0)),"") | F33: =IFERROR(INDEX($G$13:$G$19,MATCH($B33,$B$13:$B$19,0)),"") | G33: =IFERROR(INDEX($H$13:$H$19,MATCH($B33,$B$13:$B$19,0)),"")
A34: Item 5 | B34: =B26 | C34: =IFERROR(INDEX($D$13:$D$19,MATCH($B34,$B$13:$B$19,0)),"") | D34: =IFERROR(INDEX($E$13:$E$19,MATCH($B34,$B$13:$B$19,0)),"") | E34: =IFERROR(INDEX($F$13:$F$19,MATCH($B34,$B$13:$B$19,0)),"") | F34: =IFERROR(INDEX($G$13:$G$19,MATCH($B34,$B$13:$B$19,0)),"") | G34: =IFERROR(INDEX($H$13:$H$19,MATCH($B34,$B$13:$B$19,0)),"")
A35: Item Count (total rules fired) | B35: =SUM($C$13:$C$19) -> 2

Sheet _calc_Insights
A2: SECTION 1: INPUTS (from _calc_Core only)
A3: Money In This Month | B3: =calcMoneyInThisMonth -> 850
A4: Money Out This Month | B4: =calcMoneyOutThisMonth -> 165
A5: Net Cash Flow | B5: =calcNetCashFlow -> 685
A6: Transaction Count | B6: =calcTransactionCount -> 3
A7: Average Transaction | B7: =calcAverageTransaction -> 338.33333
A8: Current Month | B8: =calcCurrentMonth -> 46296
A9: Previous Month | B9: =calcPreviousMonth -> 46266
A10: Goal Progress | B10: =B77 -> 0.62
A12: SECTION 2: RULE EVALUATION
A13: RuleID | B13: Priority | C13: Fired | D13: Title | E13: Message | F13: InsightType | G13: SupportingValue | H13: Icon
A14: R1 | B14: 1 | C14: =IF(AND($B$6>0,$B$71>0),1,0) -> 1 | D14: Your biggest expense | E14: ="Your biggest expense this month was "&$B$70&" at "&CurrencySymbol&TEXT($B$71,"#,##0")&"." -> Your biggest expense this month was Supplies at $165. | F14: Spending Pattern | G14: =$B$71 -> 165 | H14: bar-chart
A15: R2 | B15: 2 | C15: =IF(AND($B$6>0,$B$73>0),1,0) -> 1 | D15: Your top vendor | E15: ="You paid "&$B$72&" more than anyone else this month, totaling "&CurrencySymbol&TEXT($B$73,"#,##0")&"." -> You paid City Wholesale Supplies more than anyone else this month, totaling $165. | F15: Vendor Pattern | G15: =$B$73 -> 165 | H15: briefcase
A16: R3 | B16: 3 | C16: =IF($B$3>0,1,0) -> 1 | D16: Income this month | E16: ="You've brought in "&CurrencySymbol&TEXT($B$3,"#,##0")&" so far this month." -> You've brought in $850 so far this month. | F16: Summary | G16: =$B$3 -> 850 | H16: trending-up
A17: R4 | B17: 4 | C17: =IF($B$6>0,1,0) -> 1 | D17: Average transaction size | E17: ="Your average transaction this month is "&CurrencySymbol&TEXT($B$7,"#,##0")&"." -> Your average transaction this month is $338. | F17: Summary | G17: =$B$7 -> 338.33333 | H17: activity
A18: R5 | B18: 5 | C18: =IF($B$6>0,1,0) -> 1 | D18: Transactions logged | E18: ="You've logged "&$B$6&" transaction"&IF($B$6=1,"","s")&" this month." -> You've logged 3 transactions this month. | F18: Activity | G18: =$B$6 -> 3 | H18: list
A19: R6 | B19: 6 | C19: =IF($B$74<>"",1,0) -> 1 | D19: Goal progress | E19: ="You are "&TEXT($B$77,"0%")&" of the way to your "&$B$74&" goal." -> You are 62% of the way to your Emergency Fund goal. | F19: Goal Progress | G19: =$B$77 -> 0.62 | H19: target
A21: SECTION 3: RANKING (Top 3)
A22: Slot 1 Priority | B22: {=IFERROR(SMALL(IF($C$14:$C$19=1,$B$14:$B$19),1),"")} -> 1
A23: Slot 2 Priority | B23: {=IFERROR(SMALL(IF($C$14:$C$19=1,$B$14:$B$19),2),"")} -> 2
A24: Slot 3 Priority | B24: {=IFERROR(SMALL(IF($C$14:$C$19=1,$B$14:$B$19),3),"")} -> 3
A26: SECTION 4: OUTPUT VALUES
A27: Output Item | B27: Priority | C27: Title | D27: Message | E27: InsightType | F27: SupportingValue | G27: Icon | H27: DisplayOrder
A28: Item 1 | B28: =B22 -> 1 | C28: =IFERROR(INDEX($D$14:$D$19,MATCH($B28,$B$14:$B$19,0)),"") -> Your biggest expense | D28: =IFERROR(INDEX($E$14:$E$19,MATCH($B28,$B$14:$B$19,0)),"") -> Your biggest expense this month was Supplies at $165. | E28: =IFERROR(INDEX($F$14:$F$19,MATCH($B28,$B$14:$B$19,0)),"") -> Spending Pattern | F28: =IFERROR(INDEX($G$14:$G$19,MATCH($B28,$B$14:$B$19,0)),"") -> 165 | G28: =IFERROR(INDEX($H$14:$H$19,MATCH($B28,$B$14:$B$19,0)),"") -> bar-chart | H28: 1
A29: Item 2 | B29: =B23 -> 2 | C29: =IFERROR(INDEX($D$14:$D$19,MATCH($B29,$B$14:$B$19,0)),"") -> Your top vendor | D29: =IFERROR(INDEX($E$14:$E$19,MATCH($B29,$B$14:$B$19,0)),"") -> You paid City Wholesale Supplies more than anyone else this month, totaling $165. | E29: =IFERROR(INDEX($F$14:$F$19,MATCH($B29,$B$14:$B$19,0)),"") -> Vendor Pattern | F29: =IFERROR(INDEX($G$14:$G$19,MATCH($B29,$B$14:$B$19,0)),"") -> 165 | G29: =IFERROR(INDEX($H$14:$H$19,MATCH($B29,$B$14:$B$19,0)),"") -> briefcase | H29: 2
A30: Item 3 | B30: =B24 -> 3 | C30: =IFERROR(INDEX($D$14:$D$19,MATCH($B30,$B$14:$B$19,0)),"") -> Income this month | D30: =IFERROR(INDEX($E$14:$E$19,MATCH($B30,$B$14:$B$19,0)),"") -> You've brought in $850 so far this month. | E30: =IFERROR(INDEX($F$14:$F$19,MATCH($B30,$B$14:$B$19,0)),"") -> Summary | F30: =IFERROR(INDEX($G$14:$G$19,MATCH($B30,$B$14:$B$19,0)),"") -> 850 | G30: =IFERROR(INDEX($H$14:$H$19,MATCH($B30,$B$14:$B$19,0)),"") -> trending-up | H30: 3
A31: Insight Item Count (total rules fired) | B31: =SUM($C$14:$C$19) -> 6
A33: SECTION 5: LOOKUP TABLES (support data)
A34: Category Spend This Month (helper)
A35: CategoryID | B35: CategoryName | C35: SpendThisMonth
A36: =IFERROR(INDEX(tbl_Categories[CategoryID],1),"") -> CAT-001 | B36: =IFERROR(INDEX(tbl_Categories[CategoryName],1),"") -> Client payments | C36: =IF(A36="","",SUMIFS(tbl_Transactions[Amount],tbl_Transactions[CategoryID],A36,tbl_Transactions[Direction],"Out",tbl_Transactions[Date],">="&$B$8,tbl_Transactions[Date],"<"&EDATE($B$8,1))) -> 0
A37: =IFERROR(INDEX(tbl_Categories[CategoryID],2),"") -> CAT-002 | B37: =IFERROR(INDEX(tbl_Categories[CategoryName],2),"") -> Product sales | C37: =IF(A37="","",SUMIFS(tbl_Transactions[Amount],tbl_Transactions[CategoryID],A37,tbl_Transactions[Direction],"Out",tbl_Transactions[Date],">="&$B$8,tbl_Transactions[Date],"<"&EDATE($B$8,1))) -> 0
A38: =IFERROR(INDEX(tbl_Categories[CategoryID],3),"") -> CAT-003 | B38: =IFERROR(INDEX(tbl_Categories[CategoryName],3),"") -> Other income | C38: =IF(A38="","",SUMIFS(tbl_Transactions[Amount],tbl_Transactions[CategoryID],A38,tbl_Transactions[Direction],"Out",tbl_Transactions[Date],">="&$B$8,tbl_Transactions[Date],"<"&EDATE($B$8,1))) -> 0
A39: =IFERROR(INDEX(tbl_Categories[CategoryID],4),"") -> CAT-004 | B39: =IFERROR(INDEX(tbl_Categories[CategoryName],4),"") -> Rent | C39: =IF(A39="","",SUMIFS(tbl_Transactions[Amount],tbl_Transactions[CategoryID],A39,tbl_Transactions[Direction],"Out",tbl_Transactions[Date],">="&$B$8,tbl_Transactions[Date],"<"&EDATE($B$8,1))) -> 0
A40: =IFERROR(INDEX(tbl_Categories[CategoryID],5),"") -> CAT-005 | B40: =IFERROR(INDEX(tbl_Categories[CategoryName],5),"") -> Utilities | C40: =IF(A40="","",SUMIFS(tbl_Transactions[Amount],tbl_Transactions[CategoryID],A40,tbl_Transactions[Direction],"Out",tbl_Transactions[Date],">="&$B$8,tbl_Transactions[Date],"<"&EDATE($B$8,1))) -> 0
A41: =IFERROR(INDEX(tbl_Categories[CategoryID],6),"") -> CAT-006 | B41: =IFERROR(INDEX(tbl_Categories[CategoryName],6),"") -> Software subscriptions | C41: =IF(A41="","",SUMIFS(tbl_Transactions[Amount],tbl_Transactions[CategoryID],A41,tbl_Transactions[Direction],"Out",tbl_Transactions[Date],">="&$B$8,tbl_Transactions[Date],"<"&EDATE($B$8,1))) -> 0
A42: =IFERROR(INDEX(tbl_Categories[CategoryID],7),"") -> CAT-007 | B42: =IFERROR(INDEX(tbl_Categories[CategoryName],7),"") -> Supplies | C42: =IF(A42="","",SUMIFS(tbl_Transactions[Amount],tbl_Transactions[CategoryID],A42,tbl_Transactions[Direction],"Out",tbl_Transactions[Date],">="&$B$8,tbl_Transactions[Date],"<"&EDATE($B$8,1))) -> 165
A43: =IFERROR(INDEX(tbl_Categories[CategoryID],8),"") -> CAT-008 | B43: =IFERROR(INDEX(tbl_Categories[CategoryName],8),"") -> Payroll | C43: =IF(A43="","",SUMIFS(tbl_Transactions[Amount],tbl_Transactions[CategoryID],A43,tbl_Transactions[Direction],"Out",tbl_Transactions[Date],">="&$B$8,tbl_Transactions[Date],"<"&EDATE($B$8,1))) -> 0
A44: =IFERROR(INDEX(tbl_Categories[CategoryID],9),"") -> CAT-009 | B44: =IFERROR(INDEX(tbl_Categories[CategoryName],9),"") -> Marketing | C44: =IF(A44="","",SUMIFS(tbl_Transactions[Amount],tbl_Transactions[CategoryID],A44,tbl_Transactions[Direction],"Out",tbl_Transactions[Date],">="&$B$8,tbl_Transactions[Date],"<"&EDATE($B$8,1))) -> 0
A45: =IFERROR(INDEX(tbl_Categories[CategoryID],10),"") -> CAT-010 | B45: =IFERROR(INDEX(tbl_Categories[CategoryName],10),"") -> Insurance | C45: =IF(A45="","",SUMIFS(tbl_Transactions[Amount],tbl_Transactions[CategoryID],A45,tbl_Transactions[Direction],"Out",tbl_Transactions[Date],">="&$B$8,tbl_Transactions[Date],"<"&EDATE($B$8,1))) -> 0
...

Sheet _lists_Validation
A1: Currency | B1: Industry | C1: Month | D1: WeekStart | E1: TimeZone | F1: Theme | G1: DateFormat | H1: NumberFormat | I1: TransactionDirection | J1: CategoryDirection | K1: BooleanChoice | L1: BillStatus | M1: RecurrenceFrequency | N1: InvoiceStatus | O1: GoalType | P1: GoalStatus | R1: PayeeNames | T1: CurrencyCode | U1: CurrencySymbol
A2: USD | B2: Freelance | C2: January | D2: Sunday | E2: America/New_York | F2: Light | G2: MM/DD/YYYY | H2: US format | I2: In | J2: In | K2: TRUE | L2: Upcoming | M2: Weekly | N2: Draft | O2: Savings | P2: Active | R2: =IFERROR(IF(ROWS($R$2:R2)<=ROWS(tbl_Vendors[VendorName]),INDEX(tbl_Vendors[VendorName],ROWS($R$2:R2)),INDEX(tbl_Customers[CustomerName],ROWS($R$2:R2)-ROWS(tbl_Vendors[VendorName]))),"") -> City Wholesale Supplies | T2: USD | U2: $
A3: GBP | B3: Retail | C3: February | D3: Monday | E3: America/Chicago | G3: DD/MM/YYYY | H3: European format | I3: Out | J3: Out | K3: FALSE | L3: Paid | M3: Monthly | N3: Sent | O3: Revenue Target | P3: Achieved | R3: =IFERROR(IF(ROWS($R$2:R3)<=ROWS(tbl_Vendors[VendorName]),INDEX(tbl_Vendors[VendorName],ROWS($R$2:R3)),INDEX(tbl_Customers[CustomerName],ROWS($R$2:R3)-ROWS(tbl_Vendors[VendorName]))),"") -> Blue Harbor Cafe | T3: GBP | U3: £
A4: EUR | B4: Service | C4: March | E4: America/Denver | J4: Both | L4: Overdue | M4: Quarterly | N4: Paid | O4: Debt Payoff | P4: Archived | R4: =IFERROR(IF(ROWS($R$2:R4)<=ROWS(tbl_Vendors[VendorName]),INDEX(tbl_Vendors[VendorName],ROWS($R$2:R4)),INDEX(tbl_Customers[CustomerName],ROWS($R$2:R4)-ROWS(tbl_Vendors[VendorName]))),"") | T4: EUR | U4: €
A5: CAD | B5: Other | C5: April | E5: America/Los_Angeles | M5: Annually | N5: Overdue | R5: =IFERROR(IF(ROWS($R$2:R5)<=ROWS(tbl_Vendors[VendorName]),INDEX(tbl_Vendors[VendorName],ROWS($R$2:R5)),INDEX(tbl_Customers[CustomerName],ROWS($R$2:R5)-ROWS(tbl_Vendors[VendorName]))),"") | T5: CAD | U5: $
A6: AUD | C6: May | E6: UTC | M6: None | N6: Void | R6: =IFERROR(IF(ROWS($R$2:R6)<=ROWS(tbl_Vendors[VendorName]),INDEX(tbl_Vendors[VendorName],ROWS($R$2:R6)),INDEX(tbl_Customers[CustomerName],ROWS($R$2:R6)-ROWS(tbl_Vendors[VendorName]))),"") | T6: AUD | U6: $
A7: PKR | C7: June | R7: =IFERROR(IF(ROWS($R$2:R7)<=ROWS(tbl_Vendors[VendorName]),INDEX(tbl_Vendors[VendorName],ROWS($R$2:R7)),INDEX(tbl_Customers[CustomerName],ROWS($R$2:R7)-ROWS(tbl_Vendors[VendorName]))),"") | T7: PKR | U7: Rs
C8: July | R8: =IFERROR(IF(ROWS($R$2:R8)<=ROWS(tbl_Vendors[VendorName]),INDEX(tbl_Vendors[VendorName],ROWS($R$2:R8)),INDEX(tbl_Customers[CustomerName],ROWS($R$2:R8)-ROWS(tbl_Vendors[VendorName]))),"")
C9: August | R9: =IFERROR(IF(ROWS($R$2:R9)<=ROWS(tbl_Vendors[VendorName]),INDEX(tbl_Vendors[VendorName],ROWS($R$2:R9)),INDEX(tbl_Customers[CustomerName],ROWS($R$2:R9)-ROWS(tbl_Vendors[VendorName]))),"")
C10: September | R10: =IFERROR(IF(ROWS($R$2:R10)<=ROWS(tbl_Vendors[VendorName]),INDEX(tbl_Vendors[VendorName],ROWS($R$2:R10)),INDEX(tbl_Customers[CustomerName],ROWS($R$2:R10)-ROWS(tbl_Vendors[VendorName]))),"")
C11: October | R11: =IFERROR(IF(ROWS($R$2:R11)<=ROWS(tbl_Vendors[VendorName]),INDEX(tbl_Vendors[VendorName],ROWS($R$2:R11)),INDEX(tbl_Customers[CustomerName],ROWS($R$2:R11)-ROWS(tbl_Vendors[VendorName]))),"")
C12: November | R12: =IFERROR(IF(ROWS($R$2:R12)<=ROWS(tbl_Vendors[VendorName]),INDEX(tbl_Vendors[VendorName],ROWS($R$2:R12)),INDEX(tbl_Customers[CustomerName],ROWS($R$2:R12)-ROWS(tbl_Vendors[VendorName]))),"")
C13: December | R13: =IFERROR(IF(ROWS($R$2:R13)<=ROWS(tbl_Vendors[VendorName]),INDEX(tbl_Vendors[VendorName],ROWS($R$2:R13)),INDEX(tbl_Customers[CustomerName],ROWS($R$2:R13)-ROWS(tbl_Vendors[VendorName]))),"")
R14: =IFERROR(IF(ROWS($R$2:R14)<=ROWS(tbl_Vendors[VendorName]),INDEX(tbl_Vendors[VendorName],ROWS($R$2:R14)),INDEX(tbl_Customers[CustomerName],ROWS($R$2:R14)-ROWS(tbl_Vendors[VendorName]))),"")
R15: =IFERROR(IF(ROWS($R$2:R15)<=ROWS(tbl_Vendors[VendorName]),INDEX(tbl_Vendors[VendorName],ROWS($R$2:R15)),INDEX(tbl_Customers[CustomerName],ROWS($R$2:R15)-ROWS(tbl_Vendors[VendorName]))),"")
R16: =IFERROR(IF(ROWS($R$2:R16)<=ROWS(tbl_Vendors[VendorName]),INDEX(tbl_Vendors[VendorName],ROWS($R$2:R16)),INDEX(tbl_Customers[CustomerName],ROWS($R$2:R16)-ROWS(tbl_Vendors[VendorName]))),"")
R17: =IFERROR(IF(ROWS($R$2:R17)<=ROWS(tbl_Vendors[VendorName]),INDEX(tbl_Vendors[VendorName],ROWS($R$2:R17)),INDEX(tbl_Customers[CustomerName],ROWS($R$2:R17)-ROWS(tbl_Vendors[VendorName]))),"")
R18: =IFERROR(IF(ROWS($R$2:R18)<=ROWS(tbl_Vendors[VendorName]),INDEX(tbl_Vendors[VendorName],ROWS($R$2:R18)),INDEX(tbl_Customers[CustomerName],ROWS($R$2:R18)-ROWS(tbl_Vendors[VendorName]))),"")
R19: =IFERROR(IF(ROWS($R$2:R19)<=ROWS(tbl_Vendors[VendorName]),INDEX(tbl_Vendors[VendorName],ROWS($R$2:R19)),INDEX(tbl_Customers[CustomerName],ROWS($R$2:R19)-ROWS(tbl_Vendors[VendorName]))),"")
R20: =IFERROR(IF(ROWS($R$2:R20)<=ROWS(tbl_Vendors[VendorName]),INDEX(tbl_Vendors[VendorName],ROWS($R$2:R20)),INDEX(tbl_Customers[CustomerName],ROWS($R$2:R20)-ROWS(tbl_Vendors[VendorName]))),"")
R21: =IFERROR(IF(ROWS($R$2:R21)<=ROWS(tbl_Vendors[VendorName]),INDEX(tbl_Vendors[VendorName],ROWS($R$2:R21)),INDEX(tbl_Customers[CustomerName],ROWS($R$2:R21)-ROWS(tbl_Vendors[VendorName]))),"")
R22: =IFERROR(IF(ROWS($R$2:R22)<=ROWS(tbl_Vendors[VendorName]),INDEX(tbl_Vendors[VendorName],ROWS($R$2:R22)),INDEX(tbl_Customers[CustomerName],ROWS($R$2:R22)-ROWS(tbl_Vendors[VendorName]))),"")
R23: =IFERROR(IF(ROWS($R$2:R23)<=ROWS(tbl_Vendors[VendorName]),INDEX(tbl_Vendors[VendorName],ROWS($R$2:R23)),INDEX(tbl_Customers[CustomerName],ROWS($R$2:R23)-ROWS(tbl_Vendors[VendorName]))),"")
R24: =IFERROR(IF(ROWS($R$2:R24)<=ROWS(tbl_Vendors[VendorName]),INDEX(tbl_Vendors[VendorName],ROWS($R$2:R24)),INDEX(tbl_Customers[CustomerName],ROWS($R$2:R24)-ROWS(tbl_Vendors[VendorName]))),"")
R25: =IFERROR(IF(ROWS($R$2:R25)<=ROWS(tbl_Vendors[VendorName]),INDEX(tbl_Vendors[VendorName],ROWS($R$2:R25)),INDEX(tbl_Customers[CustomerName],ROWS($R$2:R25)-ROWS(tbl_Vendors[VendorName]))),"")
... R101: =IFERROR(IF(ROWS($R$2:R101)<=ROWS(tbl_Vendors[VendorName]),INDEX(tbl_Vendors[VendorName],ROWS($R$2:R101)),INDEX(tbl_Customers[CustomerName],ROWS($R$2:R101)-ROWS(tbl_Vendors[VendorName]))),"")
